<?xml version="1.0" encoding="utf-8"?>
<!-- This URDF was automatically created by SolidWorks to URDF Exporter! Originally created by Stephen Brawner (brawner@gmail.com) 
     Commit Version: 1.6.0-1-g15f4949  Build Version: 1.6.7594.29634
     For more information, please see http://wiki.ros.org/sw_urdf_exporter -->
<robot
  name="int300">
  <link
    name="base_link">
    <inertial>
      <origin
        xyz="9.7076E-05 -1.3143E-10 0.081556"
        rpy="0 0 0" />
      <mass
        value="3.7103" />
      <inertia
        ixx="0.036134"
        ixy="8.0952E-10"
        ixz="-1.9413E-05"
        iyy="0.032568"
        iyz="-4.1125E-07"
        izz="0.066552" />
    </inertial>
    <visual>
      <origin
        xyz="0 0 0"
        rpy="0 0 0" />
      <geometry>
        <mesh
          filename="package://int300/meshes/base_link.STL" />
      </geometry>
      <material
        name="">
        <color
          rgba="0.75294 0.75294 0.75294 1" />
      </material>
    </visual>
    <collision>
      <origin
        xyz="0 0 0"
        rpy="0 0 0" />
      <geometry>
        <mesh
          filename="package://int300/meshes/base_link.STL" />
      </geometry>
    </collision>

    <!-- plate -->
    <visual name="plate">
      <origin xyz="0.0 0.0 0.19" rpy="0 0 0" />
      <geometry>
        <box size="0.6 0.6 0.01"/>
      </geometry>
    </visual>
    <collision>
      <origin xyz="0.0 0.0 0.19" rpy="0 0 0" />
      <geometry>
        <box size="0.6 0.6 0.01"/>
      </geometry>
    </collision>
    <inertial>
      <mass value="0.1"/>
      <inertia ixx="0.0001" ixy="0.0" ixz="0.0" iyy="0.0001" iyz="0.0" izz="0.0001"/>
    </inertial>

  </link>

  <!-- plate >
  <link name="plate_link">
    <visual>
      <origin xyz="0 0 0" rpy="0 0 0" />
      <geometry>
          <box size="0.6 0.6 0.01"/>
      </geometry>
    </visual>
    < Base collision, mass and inertia >
    <collision>
      <origin xyz="0 0 0" rpy="0 0 0" />
      <geometry>
          <box size="0.6 0.6 0.01"/>
      </geometry>
    </collision>
    <inertial>
      <mass value="0.1"/>
      <inertia ixx="0.13" ixy="0.0" ixz="0.0" iyy="0.21" iyz="0.0" izz="0.13"/>
    </inertial>
  </link-->

   <!-- *****************************plate***************************** >
 <link
    name="plate_link">
    <inertial>
      <origin
        xyz="0 0 0"
        rpy="0 0 0" />
      <mass
        value="0" />
      <inertia
        ixx="0"
        ixy="0"
        ixz="0"
        iyy="0"
        iyz="0"
        izz="0" />
    </inertial>
    <visual>
      <origin
        xyz="0 0 0"
        rpy="0 0 0" />
      <geometry>
        <box size="0.6 0.6 0.01"/>
      </geometry>
      <material
        name="">
        <color
          rgba="1 1 1 1" />
      </material>
    </visual>
    <collision>
      <origin
        xyz="0 0 0"
        rpy="0 0 0" />
      <geometry>
        <box size="0.6 0.6 0.01"/>
      </geometry>
    </collision>
  </link>


  <joint name="plate_base_joint" type="fixed">
  <axis xyz="0 0 1"/>
  <parent link="camera_link"/>
  <child link="plate_link"/>
  <origin rpy="0 0 0" xyz="0.0 0.0 0.19"/>
 </joint-->


  <link
    name="Right_wheel">
    <inertial>
      <origin
        xyz="-1.559E-05 0.014545 0.00017805"
        rpy="0 0 0" />
      <mass
        value="0.41627" />
      <inertia
        ixx="0.00056134"
        ixy="-1.1117E-09"
        ixz="-2.8584E-09"
        iyy="0.00097314"
        iyz="1.2697E-08"
        izz="0.00056137" />
    </inertial>
    <visual>
      <origin
        xyz="0 0 0"
        rpy="0 0 0" />
      <geometry>
        <mesh
          filename="package://int300/meshes/Right_wheel.STL" />
      </geometry>
      <material
        name="">
        <color
          rgba="0.79216 0.81961 0.93333 1" />
      </material>
    </visual>
    <collision>
      <origin
        xyz="0 0 0"
        rpy="0 0 0" />
      <geometry>
        <mesh
          filename="package://int300/meshes/Right_wheel.STL" />
      </geometry>
    </collision>
  </link>
  <joint
    name="right_wheel_joint"
    type="continuous">
    <origin
      xyz="-0.0024835 -0.2775 0.039812"
      rpy="0 0 0" />
    <parent
      link="base_link" />
    <child
      link="Right_wheel" />
    <axis
      xyz="0 1 0" />
  </joint>
  <link
    name="Left_wheel">
    <inertial>
      <origin
        xyz="-1.6175E-05 0.014545 -0.000178"
        rpy="0 0 0" />
      <mass
        value="0.41627" />
      <inertia
        ixx="0.00056134"
        ixy="-1.1535E-09"
        ixz="2.9658E-09"
        iyy="0.00097314"
        iyz="-1.2693E-08"
        izz="0.00056137" />
    </inertial>
    <visual>
      <origin
        xyz="0 0 0"
        rpy="0 0 0" />
      <geometry>
        <mesh
          filename="package://int300/meshes/Left_wheel.STL" />
      </geometry>
      <material
        name="">
        <color
          rgba="0.79216 0.81961 0.93333 1" />
      </material>
    </visual>
    <collision>
      <origin
        xyz="0 0 0"
        rpy="0 0 0" />
      <geometry>
        <mesh
          filename="package://int300/meshes/Left_wheel.STL" />
      </geometry>
    </collision>
  </link>
  <joint
    name="left_wheel_joint"
    type="continuous">
    <origin
      xyz="-0.0024829 0.2775 0.039812"
      rpy="3.1416 0 0" />
    <parent
      link="base_link" />
    <child
      link="Left_wheel" />
    <axis
      xyz="0 -1 0" />
  </joint>

 <!-- *****************************camera***************************** -->
 <link
    name="camera_link">
    <inertial>
      <origin
        xyz="0 0 0"
        rpy="0 0 0" />
      <mass
        value="0" />
      <inertia
        ixx="0"
        ixy="0"
        ixz="0"
        iyy="0"
        iyz="0"
        izz="0" />
    </inertial>
    <visual>
      <origin
        xyz="0 0 0"
        rpy="0 0 0" />
      <geometry>
        <mesh
          filename="package://int300/meshes/CAM.STL" />
      </geometry>
      <material
        name="">
        <color
          rgba="1 1 1 1" />
      </material>
    </visual>
    <collision>
      <origin
        xyz="0 0 0"
        rpy="0 0 0" />
      <geometry>
        <mesh
          filename="package://int300/meshes/CAM.STL" />
      </geometry>
    </collision>
  </link>

  <joint
    name="camera_joint"
    type="fixed">
    <origin
      xyz="0.281450000000119 0 0.109706094389698"
      rpy="0 0 0" />
    <parent
      link="base_link" />

    <child
      link="camera_link" />

    <axis

      xyz="0 0 1" />

  </joint>

<!-- ***********************************robotic arm*********************************************** -->

<link
    name="arm_base">
    <inertial>
      <origin
        xyz="0.0044835 -2.8604E-07 0.031338"
        rpy="0 0 0" />
      <mass
        value="0.063619" />
      <inertia
        ixx="2.2995E-05"
        ixy="1.7435E-10"
        ixz="1.5451E-07"
        iyy="2.6019E-05"
        iyz="9.4601E-12"
        izz="4.1437E-05" />
    </inertial>
    <visual>
      <origin
        xyz="0 0 0"
        rpy="0 0 0" />
      <geometry>
        <mesh
          filename="package://Totale_robotarm_urdf/meshes/base_link.STL" />
      </geometry>
      <material
        name="">
        <color
          rgba="1 1 1 1" />
      </material>
    </visual>
    <collision>
      <origin
        xyz="0 0 0"
        rpy="0 0 0" />
      <geometry>
        <mesh
          filename="package://Totale_robotarm_urdf/meshes/base_link.STL" />
      </geometry>
    </collision>
  </link>

  <joint name="arm_base_joint" type="continuous">
  <axis xyz="0 0 1"/>
  <parent link="base_link"/>
  <child link="arm_base"/>
  <origin rpy="0 0 0" xyz="0.0 0.0 0.2"/>
 </joint>

  <link
    name="Ax1_L">
    <inertial>
      <origin
        xyz="-0.000116822357136832 -0.00426355574529902 0.0168799301678951"
        rpy="0 0 0" />
      <mass
        value="0.0782567363470124" />
      <inertia
        ixx="1.56315059999613E-05"
        ixy="3.07582320716419E-07"
        ixz="1.08153567824859E-08"
        iyy="2.13405961385209E-05"
        iyz="-1.65953106655699E-21"
        izz="3.11241757719222E-05" />
    </inertial>
    <visual>
      <origin
        xyz="0 0 0"
        rpy="0 0 0" />
      <geometry>
        <mesh
          filename="package://Totale_robotarm_urdf/meshes/Ax1_L.STL" />
      </geometry>
      <material
        name="">
        <color
          rgba="1 1 1 1" />
      </material>
    </visual>
    <collision>
      <origin
        xyz="0 0 0"
        rpy="0 0 0" />
      <geometry>
        <mesh
          filename="package://Totale_robotarm_urdf/meshes/Ax1_L.STL" />
      </geometry>
    </collision>
  </link>
  <joint
    name="Ax1_J"
    type="continuous">
    <origin
      xyz="0 0 0.058"
      rpy="0 0 0" />     <!--3.1416/-->
    <parent
      link="arm_base" />
    <child
      link="Ax1_L" />
    <axis
      xyz="0 0 1" />
  </joint>
  <link
    name="Ax2_L">
    <inertial>
      <origin
        xyz="0.0283383407057589 3.83360725858539E-07 0.0642267039474669"
        rpy="0 0 0" />
      <mass
        value="0.0224992416050213" />
      <inertia
        ixx="2.39727473874096E-05"
        ixy="-1.44967888757695E-10"
        ixz="-8.44764943359058E-11"
        iyy="2.36679810921907E-05"
        iyz="-2.7361990964217E-11"
        izz="1.38096738639755E-06" />
    </inertial>
    <visual>
      <origin
        xyz="0 0 0"
        rpy="0 0 0" />
      <geometry>
        <mesh
          filename="package://Totale_robotarm_urdf/meshes/Ax2_L.STL" />
      </geometry>
      <material
        name="">
        <color
          rgba="1 1 1 1" />
      </material>
    </visual>
    <collision>
      <origin
        xyz="0 0 0"
        rpy="0 0 0" />
      <geometry>
        <mesh
          filename="package://Totale_robotarm_urdf/meshes/Ax2_L.STL" />
      </geometry>
    </collision>
  </link>
  <joint
    name="Ax2_J"
    type="continuous">
    <origin
      xyz="-0.00998 -0.0088188 0.02016"
      rpy="0 0 0" />
    <parent
      link="Ax1_L" />
    <child
      link="Ax2_L" />
    <axis
      xyz="-1 0 0" />
  </joint>
  <link
    name="Ax3_L">
    <inertial>
      <origin
        xyz="0.0138471419397028 3.03757591211262E-05 0.0508793714045985"
        rpy="0 0 0" />
      <mass
        value="0.0711576733039184" />
      <inertia
        ixx="3.99406381387016E-05"
        ixy="2.15876312841093E-22"
        ixz="3.07580745329639E-07"
        iyy="4.312721262411E-05"
        iyz="-2.78247233184919E-08"
        izz="8.82182214935736E-06" />
    </inertial>
    <visual>
      <origin
        xyz="0 0 0"
        rpy="0 0 0" />
      <geometry>
        <mesh
          filename="package://Totale_robotarm_urdf/meshes/Ax3_L.STL" />
      </geometry>
      <material
        name="">
        <color
          rgba="0 0 0 1" />
      </material>
    </visual>
    <collision>
      <origin
        xyz="0 0 0"
        rpy="0 0 0" />
      <geometry>
        <mesh
          filename="package://Totale_robotarm_urdf/meshes/Ax3_L.STL" />
      </geometry>
    </collision>
  </link>
  <joint
    name="Ax3_J"
    type="continuous">
    <origin
      xyz="0.0123 -3.1793E-05 0.12099"
      rpy="0 0 0" />
    <parent
      link="Ax2_L" />
    <child
      link="Ax3_L" />
    <axis
      xyz="-1 0 0" />
  </joint>
  <link
    name="Ax4_L">
    <inertial>
      <origin
        xyz="0.0276836189172533 -0.00217988348935882 0.0269247274990144"
        rpy="0 0 0" />
      <mass
        value="0.0176437085105226" />
      <inertia
        ixx="1.66342509955926E-06"
        ixy="-5.00425851994435E-11"
        ixz="2.06343678130449E-08"
        iyy="2.45831671151698E-06"
        iyz="-8.85802726874004E-08"
        izz="1.34205851691714E-06" />
    </inertial>
    <visual>
      <origin
        xyz="0 0 0"
        rpy="0 0 0" />
      <geometry>
        <mesh
          filename="package://Totale_robotarm_urdf/meshes/Ax4_L.STL" />
      </geometry>
      <material
        name="">
        <color
          rgba="1 1 1 1" />
      </material>
    </visual>
    <collision>
      <origin
        xyz="0 0 0"
        rpy="0 0 0" />
      <geometry>
        <mesh
          filename="package://Totale_robotarm_urdf/meshes/Ax4_L.STL" />
      </geometry>
    </collision>
  </link>
  <joint
    name="Ax4_J"
    type="continuous">
    <origin
      xyz="-0.0082999 0 0.12197"
      rpy="0 0 0" />
    <parent
      link="Ax3_L" />
    <child
      link="Ax4_L" />
    <axis
      xyz="-1 0 0" />
  </joint>
  <link
    name="Ax5_L">
    <inertial>
      <origin
        xyz="-0.00376507233640701 -0.0047117912129194 0.0168508159690375"
        rpy="0 0 0" />
      <mass
        value="0.010226424588477" />
      <inertia
        ixx="6.84201149013382E-07"
        ixy="2.04946250860037E-08"
        ixz="-1.25998850156926E-09"
        iyy="1.3154948879894E-06"
        iyz="2.39679847813738E-12"
        izz="1.22684634336986E-06" />
    </inertial>
    <visual>
      <origin
        xyz="0 0 0"
        rpy="0 0 0" />
      <geometry>
        <mesh
          filename="package://Totale_robotarm_urdf/meshes/Ax5_L.STL" />
      </geometry>
      <material
        name="">
        <color
          rgba="1 1 1 1" />
      </material>
    </visual>
    <collision>
      <origin
        xyz="0 0 0"
        rpy="0 0 0" />
      <geometry>
        <mesh
          filename="package://Totale_robotarm_urdf/meshes/Ax5_L.STL" />
      </geometry>
    </collision>
  </link>
  <joint
    name="Ax5_J"
    type="continuous">
    <origin
      xyz="0.023354 -0.0054658 0.055658"
      rpy="0 0 0" />
    <parent
      link="Ax4_L" />
    <child
      link="Ax5_L" />
    <axis
      xyz="0 0 1" />
  </joint>
  <link
    name="end_eff_L">
    <inertial>
      <origin
        xyz="-0.000144641943362108 0.00392912943683649 0.0426785499665638"
        rpy="0 0 0" />
      <mass
        value="0.00653047805448201" />
      <inertia
        ixx="6.62412249369352E-07"
        ixy="-1.16376040380085E-19"
        ixz="-9.21929181097653E-09"
        iyy="9.74088452043888E-07"
        iyz="-2.99786968239269E-20"
        izz="3.29090810819871E-07" />
    </inertial>
    <visual>
      <origin
        xyz="0 0 0"
        rpy="0 0 0" />
      <geometry>
        <mesh
          filename="package://Totale_robotarm_urdf/meshes/end_eff_L.STL" />
      </geometry>
      <material
        name="">
        <color
          rgba="1 1 1 1" />
      </material>
    </visual>
    <collision>
      <origin
        xyz="0 0 0"
        rpy="0 0 0" />
      <geometry>
        <mesh
          filename="package://Totale_robotarm_urdf/meshes/end_eff_L.STL" />
      </geometry>
    </collision>
  </link>
  <joint
    name="end_eff_J"
    type="fixed">
    <origin
      xyz="0 0 0"
      rpy="0 0 0" />
    <parent
      link="Ax5_L" />
    <child
      link="end_eff_L" />
    <axis
      xyz="0 0 0" />
  </joint>


  <!--************************************* depth camera *****************************************************************>
  <link
    name="camera_link">
    <inertial>
      <origin
        xyz="0 0 0"
        rpy="0 0 0" />
      <mass
        value="0" />
      <inertia
        ixx="0"
        ixy="0"
        ixz="0"
        iyy="0"
        iyz="0"
        izz="0" />
    </inertial>
    <visual>
      <origin
        xyz="0 0 0"
        rpy="0 0 0" />
      <geometry>
        <mesh
          filename="package://int300/meshes/CAM.STL" />
      </geometry>
      <material
        name="">
        <color
          rgba="1 1 1 1" />
      </material>
    </visual>
    <collision>
      <origin
        xyz="0 0 0"
        rpy="0 0 0" />
      <geometry>
        <mesh
          filename="package://int300/meshes/CAM.STL" />
      </geometry>
    </collision>
  </link>
  <joint
    name="camera_joint"
    type="fixed">
    <origin
      xyz="0.281450000000119 0 0.109706094389698"
      rpy="0 0 0" />
    <parent
      link="base_link" />
    <child
      link="camera_link" />
    <axis
      xyz="0 0 0" />
  </joint>


 <joint name="camera_rgb_joint" type="fixed">
    <origin xyz="0.003 0.011 0.009" rpy="0 0 0"/>
    <parent link="camera_link"/>
    <child link="camera_rgb_frame"/>
  </joint>
  <link name="camera_rgb_frame"/>

  <joint name="camera_rgb_optical_joint" type="fixed">
    <origin xyz="0 0 0" rpy="-1.57 0 -1.57"/>
    <parent link="camera_rgb_frame"/>
    <child link="camera_rgb_optical_frame"/>
  </joint>
  <link name="camera_rgb_optical_frame"/>

  <!depth camera >



<gazebo reference="camera_rgb_frame">
  <sensor name="camera_link_camera" type="depth">
    <update_rate>20</update_rate>
    <camera>
      <horizontal_fov>1.047198</horizontal_fov>
      <image>
        <width>1920</width>
        <height>1080</height>
        <format>R8G8B8</format>
      </image>
      <clip>
        <near>0.05</near>
        <far>3</far>
      </clip>
    </camera>
    <plugin name="camera_link_controller" filename="libgazebo_ros_openni_kinect.so">
      <baseline>0.2</baseline>
      <alwaysOn>true</alwaysOn>
      <updateRate>1.0</updateRate>       
      <cameraName>kinect_ir</cameraName>
      <imageTopicName>/kinect/color/image_raw</imageTopicName>
      <cameraInfoTopicName>/kinect/color/camera_info</cameraInfoTopicName>
      <depthImageTopicName>/kinect/depth/image_raw</depthImageTopicName>
      <depthImageInfoTopicName>/kinect/depth/camera_info</depthImageInfoTopicName>
      <pointCloudTopicName>/kinect/depth/points</pointCloudTopicName>
      <frameName>camera_rgb_optical_frame</frameName>
      <pointCloudCutoff>0.5</pointCloudCutoff>
      <pointCloudCutoffMax>3.0</pointCloudCutoffMax>
      <distortionK1>0.00000001</distortionK1>
      <distortionK2>0.00000001</distortionK2>
      <distortionK3>0.00000001</distortionK3>
      <distortionT1>0.00000001</distortionT1>
      <distortionT2>0.00000001</distortionT2>
      <CxPrime>0</CxPrime>
      <Cx>0</Cx>
      <Cy>0</Cy>
      <focalLength>0</focalLength>
      <hackBaseline>0</hackBaseline>
    </plugin>
  </sensor>
</gazebo-->


   <!--*******************************************DIFFDRIVE*****************************-->

  <gazebo>
    <plugin filename="libgazebo_ros_diff_drive.so" name="differential_drive_controller">
      <rosDebugLevel>Debug</rosDebugLevel>
      <robotNamespace>/</robotNamespace>
      <publishWheelTF>true</publishWheelTF>
      <publishWheelJointState>true</publishWheelJointState>
      <alwaysOn>true</alwaysOn>
      <leftJoint>left_wheel_joint</leftJoint>
      <rightJoint>right_wheel_joint</rightJoint>
      <wheelAcceleration>1.8</wheelAcceleration>
      <commandTopic>cmd_vel</commandTopic>
      <odometryTopic>odom</odometryTopic>
      <odometryFrame>odom</odometryFrame>
      <odometrySource>world</odometrySource>
      <robotBaseFrame>base_link</robotBaseFrame>
      <updateRate>10.0</updateRate>     
    </plugin>
  </gazebo>

</robot>
